INFO 2019-04-22 02:09:10,101 autoreload 578 Watching for file changes with StatReloader
INFO 2019-04-22 02:10:00,364 autoreload 578 Watching for file changes with StatReloader
INFO 2019-04-22 03:48:44,464 autoreload 578 Watching for file changes with StatReloader
ERROR 2019-04-23 00:48:40,857 exception 135 Internal Server Error: /
Traceback (most recent call last):
  File "/home/python/.virtualenvs/meiduo_mall/lib/python3.5/site-packages/django/core/cache/__init__.py", line 51, in _create_cache
    backend_cls = import_string(backend)
  File "/home/python/.virtualenvs/meiduo_mall/lib/python3.5/site-packages/django/utils/module_loading.py", line 20, in import_string
    module = import_module(module_path)
  File "/home/python/.virtualenvs/meiduo_mall/lib/python3.5/importlib/__init__.py", line 126, in import_module
    return _bootstrap._gcd_import(name[level:], package, level)
  File "<frozen importlib._bootstrap>", line 986, in _gcd_import
  File "<frozen importlib._bootstrap>", line 969, in _find_and_load
  File "<frozen importlib._bootstrap>", line 944, in _find_and_load_unlocked
  File "<frozen importlib._bootstrap>", line 222, in _call_with_frames_removed
  File "<frozen importlib._bootstrap>", line 986, in _gcd_import
  File "<frozen importlib._bootstrap>", line 969, in _find_and_load
  File "<frozen importlib._bootstrap>", line 956, in _find_and_load_unlocked
ImportError: No module named 'django_redis'

During handling of the above exception, another exception occurred:

Traceback (most recent call last):
  File "/home/python/.virtualenvs/meiduo_mall/lib/python3.5/site-packages/django/core/handlers/exception.py", line 41, in inner
    response = get_response(request)
  File "/home/python/.virtualenvs/meiduo_mall/lib/python3.5/site-packages/django/utils/deprecation.py", line 138, in __call__
    response = self.process_request(request)
  File "/home/python/.virtualenvs/meiduo_mall/lib/python3.5/site-packages/django/contrib/sessions/middleware.py", line 20, in process_request
    request.session = self.SessionStore(session_key)
  File "/home/python/.virtualenvs/meiduo_mall/lib/python3.5/site-packages/django/contrib/sessions/backends/cache.py", line 18, in __init__
    self._cache = caches[settings.SESSION_CACHE_ALIAS]
  File "/home/python/.virtualenvs/meiduo_mall/lib/python3.5/site-packages/django/core/cache/__init__.py", line 80, in __getitem__
    cache = _create_cache(alias)
  File "/home/python/.virtualenvs/meiduo_mall/lib/python3.5/site-packages/django/core/cache/__init__.py", line 54, in _create_cache
    "Could not find backend '%s': %s" % (backend, e))
django.core.cache.backends.base.InvalidCacheBackendError: Could not find backend 'django_redis.cache.RedisCache': No module named 'django_redis'
ERROR 2019-04-23 00:48:41,124 basehttp 124 "GET / HTTP/1.1" 500 93624
ERROR 2019-04-23 00:48:41,987 exception 135 Internal Server Error: /favicon.ico
Traceback (most recent call last):
  File "/home/python/.virtualenvs/meiduo_mall/lib/python3.5/site-packages/django/core/cache/__init__.py", line 51, in _create_cache
    backend_cls = import_string(backend)
  File "/home/python/.virtualenvs/meiduo_mall/lib/python3.5/site-packages/django/utils/module_loading.py", line 20, in import_string
    module = import_module(module_path)
  File "/home/python/.virtualenvs/meiduo_mall/lib/python3.5/importlib/__init__.py", line 126, in import_module
    return _bootstrap._gcd_import(name[level:], package, level)
  File "<frozen importlib._bootstrap>", line 986, in _gcd_import
  File "<frozen importlib._bootstrap>", line 969, in _find_and_load
  File "<frozen importlib._bootstrap>", line 944, in _find_and_load_unlocked
  File "<frozen importlib._bootstrap>", line 222, in _call_with_frames_removed
  File "<frozen importlib._bootstrap>", line 986, in _gcd_import
  File "<frozen importlib._bootstrap>", line 969, in _find_and_load
  File "<frozen importlib._bootstrap>", line 956, in _find_and_load_unlocked
ImportError: No module named 'django_redis'

During handling of the above exception, another exception occurred:

Traceback (most recent call last):
  File "/home/python/.virtualenvs/meiduo_mall/lib/python3.5/site-packages/django/core/handlers/exception.py", line 41, in inner
    response = get_response(request)
  File "/home/python/.virtualenvs/meiduo_mall/lib/python3.5/site-packages/django/utils/deprecation.py", line 138, in __call__
    response = self.process_request(request)
  File "/home/python/.virtualenvs/meiduo_mall/lib/python3.5/site-packages/django/contrib/sessions/middleware.py", line 20, in process_request
    request.session = self.SessionStore(session_key)
  File "/home/python/.virtualenvs/meiduo_mall/lib/python3.5/site-packages/django/contrib/sessions/backends/cache.py", line 18, in __init__
    self._cache = caches[settings.SESSION_CACHE_ALIAS]
  File "/home/python/.virtualenvs/meiduo_mall/lib/python3.5/site-packages/django/core/cache/__init__.py", line 80, in __getitem__
    cache = _create_cache(alias)
  File "/home/python/.virtualenvs/meiduo_mall/lib/python3.5/site-packages/django/core/cache/__init__.py", line 54, in _create_cache
    "Could not find backend '%s': %s" % (backend, e))
django.core.cache.backends.base.InvalidCacheBackendError: Could not find backend 'django_redis.cache.RedisCache': No module named 'django_redis'
ERROR 2019-04-23 00:48:42,141 basehttp 124 "GET /favicon.ico HTTP/1.1" 500 93666
ERROR 2019-04-23 00:48:50,477 exception 135 Internal Server Error: /register
Traceback (most recent call last):
  File "/home/python/.virtualenvs/meiduo_mall/lib/python3.5/site-packages/django/core/cache/__init__.py", line 51, in _create_cache
    backend_cls = import_string(backend)
  File "/home/python/.virtualenvs/meiduo_mall/lib/python3.5/site-packages/django/utils/module_loading.py", line 20, in import_string
    module = import_module(module_path)
  File "/home/python/.virtualenvs/meiduo_mall/lib/python3.5/importlib/__init__.py", line 126, in import_module
    return _bootstrap._gcd_import(name[level:], package, level)
  File "<frozen importlib._bootstrap>", line 986, in _gcd_import
  File "<frozen importlib._bootstrap>", line 969, in _find_and_load
  File "<frozen importlib._bootstrap>", line 944, in _find_and_load_unlocked
  File "<frozen importlib._bootstrap>", line 222, in _call_with_frames_removed
  File "<frozen importlib._bootstrap>", line 986, in _gcd_import
  File "<frozen importlib._bootstrap>", line 969, in _find_and_load
  File "<frozen importlib._bootstrap>", line 956, in _find_and_load_unlocked
ImportError: No module named 'django_redis'

During handling of the above exception, another exception occurred:

Traceback (most recent call last):
  File "/home/python/.virtualenvs/meiduo_mall/lib/python3.5/site-packages/django/core/handlers/exception.py", line 41, in inner
    response = get_response(request)
  File "/home/python/.virtualenvs/meiduo_mall/lib/python3.5/site-packages/django/utils/deprecation.py", line 138, in __call__
    response = self.process_request(request)
  File "/home/python/.virtualenvs/meiduo_mall/lib/python3.5/site-packages/django/contrib/sessions/middleware.py", line 20, in process_request
    request.session = self.SessionStore(session_key)
  File "/home/python/.virtualenvs/meiduo_mall/lib/python3.5/site-packages/django/contrib/sessions/backends/cache.py", line 18, in __init__
    self._cache = caches[settings.SESSION_CACHE_ALIAS]
  File "/home/python/.virtualenvs/meiduo_mall/lib/python3.5/site-packages/django/core/cache/__init__.py", line 80, in __getitem__
    cache = _create_cache(alias)
  File "/home/python/.virtualenvs/meiduo_mall/lib/python3.5/site-packages/django/core/cache/__init__.py", line 54, in _create_cache
    "Could not find backend '%s': %s" % (backend, e))
django.core.cache.backends.base.InvalidCacheBackendError: Could not find backend 'django_redis.cache.RedisCache': No module named 'django_redis'
ERROR 2019-04-23 00:48:50,635 basehttp 124 "GET /register HTTP/1.1" 500 93704
ERROR 2019-04-23 00:48:51,210 exception 135 Internal Server Error: /favicon.ico
Traceback (most recent call last):
  File "/home/python/.virtualenvs/meiduo_mall/lib/python3.5/site-packages/django/core/cache/__init__.py", line 51, in _create_cache
    backend_cls = import_string(backend)
  File "/home/python/.virtualenvs/meiduo_mall/lib/python3.5/site-packages/django/utils/module_loading.py", line 20, in import_string
    module = import_module(module_path)
  File "/home/python/.virtualenvs/meiduo_mall/lib/python3.5/importlib/__init__.py", line 126, in import_module
    return _bootstrap._gcd_import(name[level:], package, level)
  File "<frozen importlib._bootstrap>", line 986, in _gcd_import
  File "<frozen importlib._bootstrap>", line 969, in _find_and_load
  File "<frozen importlib._bootstrap>", line 944, in _find_and_load_unlocked
  File "<frozen importlib._bootstrap>", line 222, in _call_with_frames_removed
  File "<frozen importlib._bootstrap>", line 986, in _gcd_import
  File "<frozen importlib._bootstrap>", line 969, in _find_and_load
  File "<frozen importlib._bootstrap>", line 956, in _find_and_load_unlocked
ImportError: No module named 'django_redis'

During handling of the above exception, another exception occurred:

Traceback (most recent call last):
  File "/home/python/.virtualenvs/meiduo_mall/lib/python3.5/site-packages/django/core/handlers/exception.py", line 41, in inner
    response = get_response(request)
  File "/home/python/.virtualenvs/meiduo_mall/lib/python3.5/site-packages/django/utils/deprecation.py", line 138, in __call__
    response = self.process_request(request)
  File "/home/python/.virtualenvs/meiduo_mall/lib/python3.5/site-packages/django/contrib/sessions/middleware.py", line 20, in process_request
    request.session = self.SessionStore(session_key)
  File "/home/python/.virtualenvs/meiduo_mall/lib/python3.5/site-packages/django/contrib/sessions/backends/cache.py", line 18, in __init__
    self._cache = caches[settings.SESSION_CACHE_ALIAS]
  File "/home/python/.virtualenvs/meiduo_mall/lib/python3.5/site-packages/django/core/cache/__init__.py", line 80, in __getitem__
    cache = _create_cache(alias)
  File "/home/python/.virtualenvs/meiduo_mall/lib/python3.5/site-packages/django/core/cache/__init__.py", line 54, in _create_cache
    "Could not find backend '%s': %s" % (backend, e))
django.core.cache.backends.base.InvalidCacheBackendError: Could not find backend 'django_redis.cache.RedisCache': No module named 'django_redis'
ERROR 2019-04-23 00:48:51,295 basehttp 124 "GET /favicon.ico HTTP/1.1" 500 93674
