INFO 2019-04-22 02:09:10,101 autoreload 578 Watching for file changes with StatReloader
INFO 2019-04-22 02:10:00,364 autoreload 578 Watching for file changes with StatReloader
INFO 2019-04-22 03:48:44,464 autoreload 578 Watching for file changes with StatReloader
ERROR 2019-04-23 00:48:40,857 exception 135 Internal Server Error: /
Traceback (most recent call last):
  File "/home/python/.virtualenvs/meiduo_mall/lib/python3.5/site-packages/django/core/cache/__init__.py", line 51, in _create_cache
    backend_cls = import_string(backend)
  File "/home/python/.virtualenvs/meiduo_mall/lib/python3.5/site-packages/django/utils/module_loading.py", line 20, in import_string
    module = import_module(module_path)
  File "/home/python/.virtualenvs/meiduo_mall/lib/python3.5/importlib/__init__.py", line 126, in import_module
    return _bootstrap._gcd_import(name[level:], package, level)
  File "<frozen importlib._bootstrap>", line 986, in _gcd_import
  File "<frozen importlib._bootstrap>", line 969, in _find_and_load
  File "<frozen importlib._bootstrap>", line 944, in _find_and_load_unlocked
  File "<frozen importlib._bootstrap>", line 222, in _call_with_frames_removed
  File "<frozen importlib._bootstrap>", line 986, in _gcd_import
  File "<frozen importlib._bootstrap>", line 969, in _find_and_load
  File "<frozen importlib._bootstrap>", line 956, in _find_and_load_unlocked
ImportError: No module named 'django_redis'

During handling of the above exception, another exception occurred:

Traceback (most recent call last):
  File "/home/python/.virtualenvs/meiduo_mall/lib/python3.5/site-packages/django/core/handlers/exception.py", line 41, in inner
    response = get_response(request)
  File "/home/python/.virtualenvs/meiduo_mall/lib/python3.5/site-packages/django/utils/deprecation.py", line 138, in __call__
    response = self.process_request(request)
  File "/home/python/.virtualenvs/meiduo_mall/lib/python3.5/site-packages/django/contrib/sessions/middleware.py", line 20, in process_request
    request.session = self.SessionStore(session_key)
  File "/home/python/.virtualenvs/meiduo_mall/lib/python3.5/site-packages/django/contrib/sessions/backends/cache.py", line 18, in __init__
    self._cache = caches[settings.SESSION_CACHE_ALIAS]
  File "/home/python/.virtualenvs/meiduo_mall/lib/python3.5/site-packages/django/core/cache/__init__.py", line 80, in __getitem__
    cache = _create_cache(alias)
  File "/home/python/.virtualenvs/meiduo_mall/lib/python3.5/site-packages/django/core/cache/__init__.py", line 54, in _create_cache
    "Could not find backend '%s': %s" % (backend, e))
django.core.cache.backends.base.InvalidCacheBackendError: Could not find backend 'django_redis.cache.RedisCache': No module named 'django_redis'
ERROR 2019-04-23 00:48:41,124 basehttp 124 "GET / HTTP/1.1" 500 93624
ERROR 2019-04-23 00:48:41,987 exception 135 Internal Server Error: /favicon.ico
Traceback (most recent call last):
  File "/home/python/.virtualenvs/meiduo_mall/lib/python3.5/site-packages/django/core/cache/__init__.py", line 51, in _create_cache
    backend_cls = import_string(backend)
  File "/home/python/.virtualenvs/meiduo_mall/lib/python3.5/site-packages/django/utils/module_loading.py", line 20, in import_string
    module = import_module(module_path)
  File "/home/python/.virtualenvs/meiduo_mall/lib/python3.5/importlib/__init__.py", line 126, in import_module
    return _bootstrap._gcd_import(name[level:], package, level)
  File "<frozen importlib._bootstrap>", line 986, in _gcd_import
  File "<frozen importlib._bootstrap>", line 969, in _find_and_load
  File "<frozen importlib._bootstrap>", line 944, in _find_and_load_unlocked
  File "<frozen importlib._bootstrap>", line 222, in _call_with_frames_removed
  File "<frozen importlib._bootstrap>", line 986, in _gcd_import
  File "<frozen importlib._bootstrap>", line 969, in _find_and_load
  File "<frozen importlib._bootstrap>", line 956, in _find_and_load_unlocked
ImportError: No module named 'django_redis'

During handling of the above exception, another exception occurred:

Traceback (most recent call last):
  File "/home/python/.virtualenvs/meiduo_mall/lib/python3.5/site-packages/django/core/handlers/exception.py", line 41, in inner
    response = get_response(request)
  File "/home/python/.virtualenvs/meiduo_mall/lib/python3.5/site-packages/django/utils/deprecation.py", line 138, in __call__
    response = self.process_request(request)
  File "/home/python/.virtualenvs/meiduo_mall/lib/python3.5/site-packages/django/contrib/sessions/middleware.py", line 20, in process_request
    request.session = self.SessionStore(session_key)
  File "/home/python/.virtualenvs/meiduo_mall/lib/python3.5/site-packages/django/contrib/sessions/backends/cache.py", line 18, in __init__
    self._cache = caches[settings.SESSION_CACHE_ALIAS]
  File "/home/python/.virtualenvs/meiduo_mall/lib/python3.5/site-packages/django/core/cache/__init__.py", line 80, in __getitem__
    cache = _create_cache(alias)
  File "/home/python/.virtualenvs/meiduo_mall/lib/python3.5/site-packages/django/core/cache/__init__.py", line 54, in _create_cache
    "Could not find backend '%s': %s" % (backend, e))
django.core.cache.backends.base.InvalidCacheBackendError: Could not find backend 'django_redis.cache.RedisCache': No module named 'django_redis'
ERROR 2019-04-23 00:48:42,141 basehttp 124 "GET /favicon.ico HTTP/1.1" 500 93666
ERROR 2019-04-23 00:48:50,477 exception 135 Internal Server Error: /register
Traceback (most recent call last):
  File "/home/python/.virtualenvs/meiduo_mall/lib/python3.5/site-packages/django/core/cache/__init__.py", line 51, in _create_cache
    backend_cls = import_string(backend)
  File "/home/python/.virtualenvs/meiduo_mall/lib/python3.5/site-packages/django/utils/module_loading.py", line 20, in import_string
    module = import_module(module_path)
  File "/home/python/.virtualenvs/meiduo_mall/lib/python3.5/importlib/__init__.py", line 126, in import_module
    return _bootstrap._gcd_import(name[level:], package, level)
  File "<frozen importlib._bootstrap>", line 986, in _gcd_import
  File "<frozen importlib._bootstrap>", line 969, in _find_and_load
  File "<frozen importlib._bootstrap>", line 944, in _find_and_load_unlocked
  File "<frozen importlib._bootstrap>", line 222, in _call_with_frames_removed
  File "<frozen importlib._bootstrap>", line 986, in _gcd_import
  File "<frozen importlib._bootstrap>", line 969, in _find_and_load
  File "<frozen importlib._bootstrap>", line 956, in _find_and_load_unlocked
ImportError: No module named 'django_redis'

During handling of the above exception, another exception occurred:

Traceback (most recent call last):
  File "/home/python/.virtualenvs/meiduo_mall/lib/python3.5/site-packages/django/core/handlers/exception.py", line 41, in inner
    response = get_response(request)
  File "/home/python/.virtualenvs/meiduo_mall/lib/python3.5/site-packages/django/utils/deprecation.py", line 138, in __call__
    response = self.process_request(request)
  File "/home/python/.virtualenvs/meiduo_mall/lib/python3.5/site-packages/django/contrib/sessions/middleware.py", line 20, in process_request
    request.session = self.SessionStore(session_key)
  File "/home/python/.virtualenvs/meiduo_mall/lib/python3.5/site-packages/django/contrib/sessions/backends/cache.py", line 18, in __init__
    self._cache = caches[settings.SESSION_CACHE_ALIAS]
  File "/home/python/.virtualenvs/meiduo_mall/lib/python3.5/site-packages/django/core/cache/__init__.py", line 80, in __getitem__
    cache = _create_cache(alias)
  File "/home/python/.virtualenvs/meiduo_mall/lib/python3.5/site-packages/django/core/cache/__init__.py", line 54, in _create_cache
    "Could not find backend '%s': %s" % (backend, e))
django.core.cache.backends.base.InvalidCacheBackendError: Could not find backend 'django_redis.cache.RedisCache': No module named 'django_redis'
ERROR 2019-04-23 00:48:50,635 basehttp 124 "GET /register HTTP/1.1" 500 93704
ERROR 2019-04-23 00:48:51,210 exception 135 Internal Server Error: /favicon.ico
Traceback (most recent call last):
  File "/home/python/.virtualenvs/meiduo_mall/lib/python3.5/site-packages/django/core/cache/__init__.py", line 51, in _create_cache
    backend_cls = import_string(backend)
  File "/home/python/.virtualenvs/meiduo_mall/lib/python3.5/site-packages/django/utils/module_loading.py", line 20, in import_string
    module = import_module(module_path)
  File "/home/python/.virtualenvs/meiduo_mall/lib/python3.5/importlib/__init__.py", line 126, in import_module
    return _bootstrap._gcd_import(name[level:], package, level)
  File "<frozen importlib._bootstrap>", line 986, in _gcd_import
  File "<frozen importlib._bootstrap>", line 969, in _find_and_load
  File "<frozen importlib._bootstrap>", line 944, in _find_and_load_unlocked
  File "<frozen importlib._bootstrap>", line 222, in _call_with_frames_removed
  File "<frozen importlib._bootstrap>", line 986, in _gcd_import
  File "<frozen importlib._bootstrap>", line 969, in _find_and_load
  File "<frozen importlib._bootstrap>", line 956, in _find_and_load_unlocked
ImportError: No module named 'django_redis'

During handling of the above exception, another exception occurred:

Traceback (most recent call last):
  File "/home/python/.virtualenvs/meiduo_mall/lib/python3.5/site-packages/django/core/handlers/exception.py", line 41, in inner
    response = get_response(request)
  File "/home/python/.virtualenvs/meiduo_mall/lib/python3.5/site-packages/django/utils/deprecation.py", line 138, in __call__
    response = self.process_request(request)
  File "/home/python/.virtualenvs/meiduo_mall/lib/python3.5/site-packages/django/contrib/sessions/middleware.py", line 20, in process_request
    request.session = self.SessionStore(session_key)
  File "/home/python/.virtualenvs/meiduo_mall/lib/python3.5/site-packages/django/contrib/sessions/backends/cache.py", line 18, in __init__
    self._cache = caches[settings.SESSION_CACHE_ALIAS]
  File "/home/python/.virtualenvs/meiduo_mall/lib/python3.5/site-packages/django/core/cache/__init__.py", line 80, in __getitem__
    cache = _create_cache(alias)
  File "/home/python/.virtualenvs/meiduo_mall/lib/python3.5/site-packages/django/core/cache/__init__.py", line 54, in _create_cache
    "Could not find backend '%s': %s" % (backend, e))
django.core.cache.backends.base.InvalidCacheBackendError: Could not find backend 'django_redis.cache.RedisCache': No module named 'django_redis'
ERROR 2019-04-23 00:48:51,295 basehttp 124 "GET /favicon.ico HTTP/1.1" 500 93674
ERROR 2019-04-23 06:14:14,913 exception 135 Internal Server Error: /
Traceback (most recent call last):
  File "/home/python/.virtualenvs/meiduo_mall/lib/python3.5/site-packages/django/core/cache/__init__.py", line 51, in _create_cache
    backend_cls = import_string(backend)
  File "/home/python/.virtualenvs/meiduo_mall/lib/python3.5/site-packages/django/utils/module_loading.py", line 20, in import_string
    module = import_module(module_path)
  File "/home/python/.virtualenvs/meiduo_mall/lib/python3.5/importlib/__init__.py", line 126, in import_module
    return _bootstrap._gcd_import(name[level:], package, level)
  File "<frozen importlib._bootstrap>", line 986, in _gcd_import
  File "<frozen importlib._bootstrap>", line 969, in _find_and_load
  File "<frozen importlib._bootstrap>", line 944, in _find_and_load_unlocked
  File "<frozen importlib._bootstrap>", line 222, in _call_with_frames_removed
  File "<frozen importlib._bootstrap>", line 986, in _gcd_import
  File "<frozen importlib._bootstrap>", line 969, in _find_and_load
  File "<frozen importlib._bootstrap>", line 956, in _find_and_load_unlocked
ImportError: No module named 'django_redis'

During handling of the above exception, another exception occurred:

Traceback (most recent call last):
  File "/home/python/.virtualenvs/meiduo_mall/lib/python3.5/site-packages/django/core/handlers/exception.py", line 41, in inner
    response = get_response(request)
  File "/home/python/.virtualenvs/meiduo_mall/lib/python3.5/site-packages/django/utils/deprecation.py", line 138, in __call__
    response = self.process_request(request)
  File "/home/python/.virtualenvs/meiduo_mall/lib/python3.5/site-packages/django/contrib/sessions/middleware.py", line 20, in process_request
    request.session = self.SessionStore(session_key)
  File "/home/python/.virtualenvs/meiduo_mall/lib/python3.5/site-packages/django/contrib/sessions/backends/cache.py", line 18, in __init__
    self._cache = caches[settings.SESSION_CACHE_ALIAS]
  File "/home/python/.virtualenvs/meiduo_mall/lib/python3.5/site-packages/django/core/cache/__init__.py", line 80, in __getitem__
    cache = _create_cache(alias)
  File "/home/python/.virtualenvs/meiduo_mall/lib/python3.5/site-packages/django/core/cache/__init__.py", line 54, in _create_cache
    "Could not find backend '%s': %s" % (backend, e))
django.core.cache.backends.base.InvalidCacheBackendError: Could not find backend 'django_redis.cache.RedisCache': No module named 'django_redis'
ERROR 2019-04-23 06:14:15,263 basehttp 124 "GET / HTTP/1.1" 500 93897
ERROR 2019-04-23 06:14:16,339 exception 135 Internal Server Error: /favicon.ico
Traceback (most recent call last):
  File "/home/python/.virtualenvs/meiduo_mall/lib/python3.5/site-packages/django/core/cache/__init__.py", line 51, in _create_cache
    backend_cls = import_string(backend)
  File "/home/python/.virtualenvs/meiduo_mall/lib/python3.5/site-packages/django/utils/module_loading.py", line 20, in import_string
    module = import_module(module_path)
  File "/home/python/.virtualenvs/meiduo_mall/lib/python3.5/importlib/__init__.py", line 126, in import_module
    return _bootstrap._gcd_import(name[level:], package, level)
  File "<frozen importlib._bootstrap>", line 986, in _gcd_import
  File "<frozen importlib._bootstrap>", line 969, in _find_and_load
  File "<frozen importlib._bootstrap>", line 944, in _find_and_load_unlocked
  File "<frozen importlib._bootstrap>", line 222, in _call_with_frames_removed
  File "<frozen importlib._bootstrap>", line 986, in _gcd_import
  File "<frozen importlib._bootstrap>", line 969, in _find_and_load
  File "<frozen importlib._bootstrap>", line 956, in _find_and_load_unlocked
ImportError: No module named 'django_redis'

During handling of the above exception, another exception occurred:

Traceback (most recent call last):
  File "/home/python/.virtualenvs/meiduo_mall/lib/python3.5/site-packages/django/core/handlers/exception.py", line 41, in inner
    response = get_response(request)
  File "/home/python/.virtualenvs/meiduo_mall/lib/python3.5/site-packages/django/utils/deprecation.py", line 138, in __call__
    response = self.process_request(request)
  File "/home/python/.virtualenvs/meiduo_mall/lib/python3.5/site-packages/django/contrib/sessions/middleware.py", line 20, in process_request
    request.session = self.SessionStore(session_key)
  File "/home/python/.virtualenvs/meiduo_mall/lib/python3.5/site-packages/django/contrib/sessions/backends/cache.py", line 18, in __init__
    self._cache = caches[settings.SESSION_CACHE_ALIAS]
  File "/home/python/.virtualenvs/meiduo_mall/lib/python3.5/site-packages/django/core/cache/__init__.py", line 80, in __getitem__
    cache = _create_cache(alias)
  File "/home/python/.virtualenvs/meiduo_mall/lib/python3.5/site-packages/django/core/cache/__init__.py", line 54, in _create_cache
    "Could not find backend '%s': %s" % (backend, e))
django.core.cache.backends.base.InvalidCacheBackendError: Could not find backend 'django_redis.cache.RedisCache': No module named 'django_redis'
ERROR 2019-04-23 06:14:16,535 basehttp 124 "GET /favicon.ico HTTP/1.1" 500 93939
ERROR 2019-04-23 06:19:36,063 exception 135 Internal Server Error: /
Traceback (most recent call last):
  File "/home/python/.virtualenvs/meiduo_mall/lib/python3.5/site-packages/django/template/utils.py", line 65, in __getitem__
    return self._engines[alias]
KeyError: 'jinja2'

During handling of the above exception, another exception occurred:

Traceback (most recent call last):
  File "/home/python/.virtualenvs/meiduo_mall/lib/python3.5/site-packages/django/core/handlers/exception.py", line 41, in inner
    response = get_response(request)
  File "/home/python/.virtualenvs/meiduo_mall/lib/python3.5/site-packages/django/core/handlers/base.py", line 187, in _get_response
    response = self.process_exception_by_middleware(e, request)
  File "/home/python/.virtualenvs/meiduo_mall/lib/python3.5/site-packages/django/core/handlers/base.py", line 185, in _get_response
    response = wrapped_callback(request, *callback_args, **callback_kwargs)
  File "/home/python/.virtualenvs/meiduo_mall/lib/python3.5/site-packages/django/views/generic/base.py", line 68, in view
    return self.dispatch(request, *args, **kwargs)
  File "/home/python/.virtualenvs/meiduo_mall/lib/python3.5/site-packages/django/views/generic/base.py", line 88, in dispatch
    return handler(request, *args, **kwargs)
  File "/home/python/Desktop/meiduo_project/meiduo_mall/meiduo_mall/apps/contents/views.py", line 12, in get
    return render(request, 'index.html')
  File "/home/python/.virtualenvs/meiduo_mall/lib/python3.5/site-packages/django/shortcuts.py", line 30, in render
    content = loader.render_to_string(template_name, context, request, using=using)
  File "/home/python/.virtualenvs/meiduo_mall/lib/python3.5/site-packages/django/template/loader.py", line 67, in render_to_string
    template = get_template(template_name, using=using)
  File "/home/python/.virtualenvs/meiduo_mall/lib/python3.5/site-packages/django/template/loader.py", line 18, in get_template
    engines = _engine_list(using)
  File "/home/python/.virtualenvs/meiduo_mall/lib/python3.5/site-packages/django/template/loader.py", line 72, in _engine_list
    return engines.all() if using is None else [engines[using]]
  File "/home/python/.virtualenvs/meiduo_mall/lib/python3.5/site-packages/django/template/utils.py", line 89, in all
    return [self[alias] for alias in self]
  File "/home/python/.virtualenvs/meiduo_mall/lib/python3.5/site-packages/django/template/utils.py", line 89, in <listcomp>
    return [self[alias] for alias in self]
  File "/home/python/.virtualenvs/meiduo_mall/lib/python3.5/site-packages/django/template/utils.py", line 79, in __getitem__
    engine_cls = import_string(backend)
  File "/home/python/.virtualenvs/meiduo_mall/lib/python3.5/site-packages/django/utils/module_loading.py", line 20, in import_string
    module = import_module(module_path)
  File "/home/python/.virtualenvs/meiduo_mall/lib/python3.5/importlib/__init__.py", line 126, in import_module
    return _bootstrap._gcd_import(name[level:], package, level)
  File "<frozen importlib._bootstrap>", line 986, in _gcd_import
  File "<frozen importlib._bootstrap>", line 969, in _find_and_load
  File "<frozen importlib._bootstrap>", line 958, in _find_and_load_unlocked
  File "<frozen importlib._bootstrap>", line 673, in _load_unlocked
  File "<frozen importlib._bootstrap_external>", line 665, in exec_module
  File "<frozen importlib._bootstrap>", line 222, in _call_with_frames_removed
  File "/home/python/.virtualenvs/meiduo_mall/lib/python3.5/site-packages/django/template/backends/jinja2.py", line 6, in <module>
    import jinja2
ImportError: No module named 'jinja2'
ERROR 2019-04-23 06:19:36,478 basehttp 124 "GET / HTTP/1.1" 500 137182
WARNING 2019-04-23 06:19:38,149 base 152 Not Found: /favicon.ico
WARNING 2019-04-23 06:19:38,150 basehttp 124 "GET /favicon.ico HTTP/1.1" 404 2424
ERROR 2019-04-23 06:20:32,299 exception 135 Internal Server Error: /
Traceback (most recent call last):
  File "/home/python/.virtualenvs/meiduo_mall/lib/python3.5/site-packages/django/core/handlers/exception.py", line 41, in inner
    response = get_response(request)
  File "/home/python/.virtualenvs/meiduo_mall/lib/python3.5/site-packages/django/core/handlers/base.py", line 187, in _get_response
    response = self.process_exception_by_middleware(e, request)
  File "/home/python/.virtualenvs/meiduo_mall/lib/python3.5/site-packages/django/core/handlers/base.py", line 185, in _get_response
    response = wrapped_callback(request, *callback_args, **callback_kwargs)
  File "/home/python/.virtualenvs/meiduo_mall/lib/python3.5/site-packages/django/views/generic/base.py", line 68, in view
    return self.dispatch(request, *args, **kwargs)
  File "/home/python/.virtualenvs/meiduo_mall/lib/python3.5/site-packages/django/views/generic/base.py", line 88, in dispatch
    return handler(request, *args, **kwargs)
  File "/home/python/Desktop/meiduo_project/meiduo_mall/meiduo_mall/apps/contents/views.py", line 12, in get
    return render(request, 'index.html')
  File "/home/python/.virtualenvs/meiduo_mall/lib/python3.5/site-packages/django/shortcuts.py", line 30, in render
    content = loader.render_to_string(template_name, context, request, using=using)
  File "/home/python/.virtualenvs/meiduo_mall/lib/python3.5/site-packages/django/template/loader.py", line 67, in render_to_string
    template = get_template(template_name, using=using)
  File "/home/python/.virtualenvs/meiduo_mall/lib/python3.5/site-packages/django/template/loader.py", line 25, in get_template
    raise TemplateDoesNotExist(template_name, chain=chain)
django.template.exceptions.TemplateDoesNotExist: index.html
ERROR 2019-04-23 06:20:32,383 basehttp 124 "GET / HTTP/1.1" 500 97409
INFO 2019-04-23 06:23:25,168 basehttp 124 "GET / HTTP/1.1" 200 25127
INFO 2019-04-23 06:23:25,260 basehttp 124 "GET /static/css/reset.css HTTP/1.1" 200 638
INFO 2019-04-23 06:23:25,367 basehttp 124 "GET /static/css/main.css HTTP/1.1" 200 39722
INFO 2019-04-23 06:23:25,387 basehttp 124 "GET /static/js/axios-0.18.0.min.js HTTP/1.1" 200 12941
INFO 2019-04-23 06:23:25,399 basehttp 124 "GET /static/js/slide.js HTTP/1.1" 200 1822
INFO 2019-04-23 06:23:25,403 basehttp 124 "GET /static/js/common.js HTTP/1.1" 200 891
INFO 2019-04-23 06:23:25,407 basehttp 124 "GET /static/js/index.js HTTP/1.1" 200 1418
INFO 2019-04-23 06:23:25,453 basehttp 124 "GET /static/images/logo.png HTTP/1.1" 200 7450
INFO 2019-04-23 06:23:25,496 basehttp 124 "GET /static/js/host.js HTTP/1.1" 200 120
INFO 2019-04-23 06:23:25,513 basehttp 124 "GET /static/js/jquery-1.12.4.min.js HTTP/1.1" 200 97163
INFO 2019-04-23 06:23:25,528 basehttp 124 "GET /static/images/goods/goods001.jpg HTTP/1.1" 200 5391
INFO 2019-04-23 06:23:25,604 basehttp 124 "GET /static/images/goods/goods002.jpg HTTP/1.1" 200 5377
INFO 2019-04-23 06:23:25,633 basehttp 124 "GET /static/js/vue-2.5.16.js HTTP/1.1" 200 289307
INFO 2019-04-23 06:23:25,707 basehttp 124 "GET /static/images/slide01.jpg HTTP/1.1" 200 67813
INFO 2019-04-23 06:23:25,720 basehttp 124 "GET /static/images/slide03.jpg HTTP/1.1" 200 70152
INFO 2019-04-23 06:23:25,723 basehttp 124 "GET /static/images/slide04.jpg HTTP/1.1" 200 107973
INFO 2019-04-23 06:23:25,734 basehttp 124 "GET /static/images/adv01.jpg HTTP/1.1" 200 39831
INFO 2019-04-23 06:23:25,713 basehttp 124 "GET /static/images/slide02.jpg HTTP/1.1" 200 89905
INFO 2019-04-23 06:23:25,727 basehttp 124 "GET /static/images/banner01.jpg HTTP/1.1" 200 23658
INFO 2019-04-23 06:23:25,820 basehttp 124 "GET /static/images/goods/goods003.jpg HTTP/1.1" 200 8579
INFO 2019-04-23 06:23:25,826 basehttp 124 "GET /static/images/goods/goods004.jpg HTTP/1.1" 200 6565
INFO 2019-04-23 06:23:25,835 basehttp 124 "GET /static/images/goods/goods005.jpg HTTP/1.1" 200 7578
INFO 2019-04-23 06:23:25,837 basehttp 124 "GET /static/images/banner02.jpg HTTP/1.1" 200 26729
INFO 2019-04-23 06:23:25,843 basehttp 124 "GET /static/images/goods/goods008.jpg HTTP/1.1" 200 7072
INFO 2019-04-23 06:23:25,851 basehttp 124 "GET /static/images/banner03.jpg HTTP/1.1" 200 22681
INFO 2019-04-23 06:23:25,883 basehttp 124 "GET /static/images/goods/goods009.jpg HTTP/1.1" 200 8738
INFO 2019-04-23 06:23:26,803 basehttp 124 "GET /static/images/icons.png HTTP/1.1" 200 7740
INFO 2019-04-23 06:25:54,369 basehttp 124 "GET / HTTP/1.1" 302 0
INFO 2019-04-23 06:25:54,374 basehttp 124 "GET / HTTP/1.1" 302 0
INFO 2019-04-23 06:25:54,383 basehttp 124 "GET / HTTP/1.1" 302 0
INFO 2019-04-23 06:25:54,418 basehttp 124 "GET / HTTP/1.1" 302 0
INFO 2019-04-23 06:25:54,422 basehttp 124 "GET / HTTP/1.1" 302 0
INFO 2019-04-23 06:25:54,431 basehttp 124 "GET / HTTP/1.1" 302 0
INFO 2019-04-23 06:25:54,435 basehttp 124 "GET / HTTP/1.1" 302 0
INFO 2019-04-23 06:25:54,443 basehttp 124 "GET / HTTP/1.1" 302 0
INFO 2019-04-23 06:25:54,458 basehttp 124 "GET / HTTP/1.1" 302 0
INFO 2019-04-23 06:25:54,464 basehttp 124 "GET / HTTP/1.1" 302 0
INFO 2019-04-23 06:25:54,482 basehttp 124 "GET / HTTP/1.1" 302 0
INFO 2019-04-23 06:25:54,488 basehttp 124 "GET / HTTP/1.1" 302 0
INFO 2019-04-23 06:25:54,508 basehttp 124 "GET / HTTP/1.1" 302 0
INFO 2019-04-23 06:25:54,529 basehttp 124 "GET / HTTP/1.1" 302 0
INFO 2019-04-23 06:25:54,569 basehttp 124 "GET / HTTP/1.1" 302 0
INFO 2019-04-23 06:25:54,594 basehttp 124 "GET / HTTP/1.1" 302 0
INFO 2019-04-23 06:25:54,616 basehttp 124 "GET / HTTP/1.1" 302 0
INFO 2019-04-23 06:25:54,645 basehttp 124 "GET / HTTP/1.1" 302 0
INFO 2019-04-23 06:25:54,657 basehttp 124 "GET / HTTP/1.1" 302 0
INFO 2019-04-23 06:25:54,681 basehttp 124 "GET / HTTP/1.1" 302 0
INFO 2019-04-23 06:25:54,694 basehttp 124 "GET / HTTP/1.1" 302 0
INFO 2019-04-23 06:25:55,687 basehttp 124 "GET / HTTP/1.1" 302 0
INFO 2019-04-23 06:25:55,700 basehttp 124 "GET / HTTP/1.1" 302 0
INFO 2019-04-23 06:25:55,716 basehttp 124 "GET / HTTP/1.1" 302 0
INFO 2019-04-23 06:25:55,752 basehttp 124 "GET / HTTP/1.1" 302 0
INFO 2019-04-23 06:25:55,770 basehttp 124 "GET / HTTP/1.1" 302 0
INFO 2019-04-23 06:25:55,785 basehttp 124 "GET / HTTP/1.1" 302 0
INFO 2019-04-23 06:25:55,796 basehttp 124 "GET / HTTP/1.1" 302 0
INFO 2019-04-23 06:25:55,817 basehttp 124 "GET / HTTP/1.1" 302 0
INFO 2019-04-23 06:25:55,835 basehttp 124 "GET / HTTP/1.1" 302 0
INFO 2019-04-23 06:25:55,855 basehttp 124 "GET / HTTP/1.1" 302 0
INFO 2019-04-23 06:25:55,875 basehttp 124 "GET / HTTP/1.1" 302 0
INFO 2019-04-23 06:25:55,889 basehttp 124 "GET / HTTP/1.1" 302 0
INFO 2019-04-23 06:25:55,902 basehttp 124 "GET / HTTP/1.1" 302 0
INFO 2019-04-23 06:25:55,913 basehttp 124 "GET / HTTP/1.1" 302 0
INFO 2019-04-23 06:25:55,923 basehttp 124 "GET / HTTP/1.1" 302 0
INFO 2019-04-23 06:25:55,940 basehttp 124 "GET / HTTP/1.1" 302 0
INFO 2019-04-23 06:25:55,955 basehttp 124 "GET / HTTP/1.1" 302 0
INFO 2019-04-23 06:25:55,975 basehttp 124 "GET / HTTP/1.1" 302 0
INFO 2019-04-23 06:25:55,985 basehttp 124 "GET / HTTP/1.1" 302 0
INFO 2019-04-23 06:25:56,030 basehttp 124 "GET / HTTP/1.1" 302 0
INFO 2019-04-23 06:25:56,040 basehttp 124 "GET / HTTP/1.1" 302 0
INFO 2019-04-23 06:26:01,055 basehttp 124 "GET / HTTP/1.1" 302 0
INFO 2019-04-23 06:26:01,068 basehttp 124 "GET / HTTP/1.1" 302 0
INFO 2019-04-23 06:26:01,103 basehttp 124 "GET / HTTP/1.1" 302 0
INFO 2019-04-23 06:26:01,107 basehttp 124 "GET / HTTP/1.1" 302 0
INFO 2019-04-23 06:26:01,111 basehttp 124 "GET / HTTP/1.1" 302 0
INFO 2019-04-23 06:26:01,138 basehttp 124 "GET / HTTP/1.1" 302 0
INFO 2019-04-23 06:26:01,157 basehttp 124 "GET / HTTP/1.1" 302 0
INFO 2019-04-23 06:26:01,163 basehttp 124 "GET / HTTP/1.1" 302 0
INFO 2019-04-23 06:26:01,184 basehttp 124 "GET / HTTP/1.1" 302 0
INFO 2019-04-23 06:26:01,204 basehttp 124 "GET / HTTP/1.1" 302 0
INFO 2019-04-23 06:26:01,224 basehttp 124 "GET / HTTP/1.1" 302 0
INFO 2019-04-23 06:26:01,241 basehttp 124 "GET / HTTP/1.1" 302 0
INFO 2019-04-23 06:26:01,263 basehttp 124 "GET / HTTP/1.1" 302 0
INFO 2019-04-23 06:26:01,276 basehttp 124 "GET / HTTP/1.1" 302 0
INFO 2019-04-23 06:26:01,285 basehttp 124 "GET / HTTP/1.1" 302 0
INFO 2019-04-23 06:26:01,319 basehttp 124 "GET / HTTP/1.1" 302 0
INFO 2019-04-23 06:26:01,330 basehttp 124 "GET / HTTP/1.1" 302 0
INFO 2019-04-23 06:26:01,348 basehttp 124 "GET / HTTP/1.1" 302 0
INFO 2019-04-23 06:26:01,366 basehttp 124 "GET / HTTP/1.1" 302 0
INFO 2019-04-23 06:26:01,380 basehttp 124 "GET / HTTP/1.1" 302 0
INFO 2019-04-23 06:26:01,393 basehttp 124 "GET / HTTP/1.1" 302 0
INFO 2019-04-23 06:32:06,411 basehttp 124 "GET / HTTP/1.1" 302 0
INFO 2019-04-23 06:32:06,429 basehttp 124 "GET / HTTP/1.1" 302 0
INFO 2019-04-23 06:32:06,437 basehttp 124 "GET / HTTP/1.1" 302 0
INFO 2019-04-23 06:32:06,439 basehttp 124 "GET / HTTP/1.1" 302 0
INFO 2019-04-23 06:32:06,444 basehttp 124 "GET / HTTP/1.1" 302 0
INFO 2019-04-23 06:32:06,458 basehttp 124 "GET / HTTP/1.1" 302 0
INFO 2019-04-23 06:32:06,479 basehttp 124 "GET / HTTP/1.1" 302 0
INFO 2019-04-23 06:32:06,492 basehttp 124 "GET / HTTP/1.1" 302 0
INFO 2019-04-23 06:32:06,511 basehttp 124 "GET / HTTP/1.1" 302 0
INFO 2019-04-23 06:32:06,528 basehttp 124 "GET / HTTP/1.1" 302 0
INFO 2019-04-23 06:32:06,573 basehttp 124 "GET / HTTP/1.1" 302 0
INFO 2019-04-23 06:32:06,588 basehttp 124 "GET / HTTP/1.1" 302 0
INFO 2019-04-23 06:32:06,599 basehttp 124 "GET / HTTP/1.1" 302 0
INFO 2019-04-23 06:32:06,622 basehttp 124 "GET / HTTP/1.1" 302 0
INFO 2019-04-23 06:32:06,643 basehttp 124 "GET / HTTP/1.1" 302 0
INFO 2019-04-23 06:32:06,653 basehttp 124 "GET / HTTP/1.1" 302 0
INFO 2019-04-23 06:32:06,672 basehttp 124 "GET / HTTP/1.1" 302 0
INFO 2019-04-23 06:32:06,683 basehttp 124 "GET / HTTP/1.1" 302 0
INFO 2019-04-23 06:32:06,719 basehttp 124 "GET / HTTP/1.1" 302 0
INFO 2019-04-23 06:32:06,739 basehttp 124 "GET / HTTP/1.1" 302 0
INFO 2019-04-23 06:32:06,756 basehttp 124 "GET / HTTP/1.1" 302 0
INFO 2019-04-23 06:32:07,324 basehttp 124 "GET / HTTP/1.1" 302 0
INFO 2019-04-23 06:32:07,337 basehttp 124 "GET / HTTP/1.1" 302 0
INFO 2019-04-23 06:32:07,341 basehttp 124 "GET / HTTP/1.1" 302 0
INFO 2019-04-23 06:32:07,363 basehttp 124 "GET / HTTP/1.1" 302 0
INFO 2019-04-23 06:32:07,380 basehttp 124 "GET / HTTP/1.1" 302 0
INFO 2019-04-23 06:32:07,396 basehttp 124 "GET / HTTP/1.1" 302 0
INFO 2019-04-23 06:32:07,404 basehttp 124 "GET / HTTP/1.1" 302 0
INFO 2019-04-23 06:32:07,421 basehttp 124 "GET / HTTP/1.1" 302 0
INFO 2019-04-23 06:32:07,457 basehttp 124 "GET / HTTP/1.1" 302 0
INFO 2019-04-23 06:32:07,470 basehttp 124 "GET / HTTP/1.1" 302 0
INFO 2019-04-23 06:32:07,481 basehttp 124 "GET / HTTP/1.1" 302 0
INFO 2019-04-23 06:32:07,501 basehttp 124 "GET / HTTP/1.1" 302 0
INFO 2019-04-23 06:32:07,523 basehttp 124 "GET / HTTP/1.1" 302 0
INFO 2019-04-23 06:32:07,535 basehttp 124 "GET / HTTP/1.1" 302 0
INFO 2019-04-23 06:32:07,565 basehttp 124 "GET / HTTP/1.1" 302 0
INFO 2019-04-23 06:32:07,603 basehttp 124 "GET / HTTP/1.1" 302 0
INFO 2019-04-23 06:32:07,622 basehttp 124 "GET / HTTP/1.1" 302 0
INFO 2019-04-23 06:32:07,663 basehttp 124 "GET / HTTP/1.1" 302 0
INFO 2019-04-23 06:32:07,671 basehttp 124 "GET / HTTP/1.1" 302 0
INFO 2019-04-23 06:32:07,679 basehttp 124 "GET / HTTP/1.1" 302 0
INFO 2019-04-23 06:32:07,707 basehttp 124 "GET / HTTP/1.1" 302 0
INFO 2019-04-23 06:32:12,723 basehttp 124 "GET / HTTP/1.1" 302 0
INFO 2019-04-23 06:32:12,760 basehttp 124 "GET / HTTP/1.1" 302 0
INFO 2019-04-23 06:32:12,765 basehttp 124 "GET / HTTP/1.1" 302 0
INFO 2019-04-23 06:32:12,776 basehttp 124 "GET / HTTP/1.1" 302 0
INFO 2019-04-23 06:32:12,795 basehttp 124 "GET / HTTP/1.1" 302 0
INFO 2019-04-23 06:32:12,802 basehttp 124 "GET / HTTP/1.1" 302 0
INFO 2019-04-23 06:32:12,809 basehttp 124 "GET / HTTP/1.1" 302 0
INFO 2019-04-23 06:32:12,830 basehttp 124 "GET / HTTP/1.1" 302 0
INFO 2019-04-23 06:32:12,854 basehttp 124 "GET / HTTP/1.1" 302 0
INFO 2019-04-23 06:32:12,872 basehttp 124 "GET / HTTP/1.1" 302 0
INFO 2019-04-23 06:32:12,883 basehttp 124 "GET / HTTP/1.1" 302 0
INFO 2019-04-23 06:32:12,898 basehttp 124 "GET / HTTP/1.1" 302 0
INFO 2019-04-23 06:32:12,912 basehttp 124 "GET / HTTP/1.1" 302 0
INFO 2019-04-23 06:32:12,930 basehttp 124 "GET / HTTP/1.1" 302 0
INFO 2019-04-23 06:32:12,934 basehttp 124 "GET / HTTP/1.1" 302 0
INFO 2019-04-23 06:32:12,989 basehttp 124 "GET / HTTP/1.1" 302 0
INFO 2019-04-23 06:32:12,993 basehttp 124 "GET / HTTP/1.1" 302 0
INFO 2019-04-23 06:32:13,005 basehttp 124 "GET / HTTP/1.1" 302 0
INFO 2019-04-23 06:32:13,013 basehttp 124 "GET / HTTP/1.1" 302 0
INFO 2019-04-23 06:32:13,028 basehttp 124 "GET / HTTP/1.1" 302 0
INFO 2019-04-23 06:32:13,034 basehttp 124 "GET / HTTP/1.1" 302 0
INFO 2019-04-23 06:39:03,788 basehttp 124 "GET / HTTP/1.1" 200 25127
WARNING 2019-04-23 06:39:05,142 base 152 Not Found: /favicon.ico
WARNING 2019-04-23 06:39:05,144 basehttp 124 "GET /favicon.ico HTTP/1.1" 404 2424
INFO 2019-04-23 06:39:06,646 basehttp 124 "GET /register/ HTTP/1.1" 200 326
INFO 2019-04-23 06:39:13,529 basehttp 124 "GET /register/ HTTP/1.1" 200 326
INFO 2019-04-23 06:39:55,189 basehttp 124 "GET /register/ HTTP/1.1" 200 326
INFO 2019-04-23 06:40:31,633 basehttp 124 "GET /register/ HTTP/1.1" 200 4525
INFO 2019-04-23 06:40:31,854 basehttp 124 "GET /static/images/interval_line.png HTTP/1.1" 200 1123
INFO 2019-04-23 06:40:31,882 basehttp 124 "GET /static/images/icons02.png HTTP/1.1" 200 3935
INFO 2019-04-23 06:40:31,919 basehttp 124 "GET /static/images/register_banner.png HTTP/1.1" 200 54894
INFO 2019-04-23 06:40:31,990 basehttp 124 "GET /static/js/register.js HTTP/1.1" 200 9786
WARNING 2019-04-23 06:40:54,379 csrf 160 Forbidden (CSRF token missing or incorrect.): /register/
WARNING 2019-04-23 06:40:54,393 basehttp 124 "POST /register/ HTTP/1.1" 403 2502
INFO 2019-04-23 06:58:53,678 basehttp 124 "GET /register/ HTTP/1.1" 200 4525
WARNING 2019-04-23 06:59:20,602 csrf 160 Forbidden (CSRF token missing or incorrect.): /register/
WARNING 2019-04-23 06:59:20,608 basehttp 124 "POST /register/ HTTP/1.1" 403 2502
INFO 2019-04-23 07:49:45,832 basehttp 124 "GET /register/ HTTP/1.1" 200 4525
WARNING 2019-04-23 07:50:09,592 csrf 160 Forbidden (CSRF token missing or incorrect.): /register/
WARNING 2019-04-23 07:50:09,594 basehttp 124 "POST /register/ HTTP/1.1" 403 2502
ERROR 2019-04-23 07:53:36,322 exception 135 Internal Server Error: /register/
Traceback (most recent call last):
  File "/home/python/.virtualenvs/meiduo_mall/lib/python3.5/site-packages/django/template/backends/jinja2.py", line 45, in get_template
    return Template(self.env.get_template(template_name), self)
  File "/home/python/.virtualenvs/meiduo_mall/lib/python3.5/site-packages/jinja2/environment.py", line 830, in get_template
    return self._load_template(name, self.make_globals(globals))
  File "/home/python/.virtualenvs/meiduo_mall/lib/python3.5/site-packages/jinja2/environment.py", line 804, in _load_template
    template = self.loader.load(self, name, globals)
  File "/home/python/.virtualenvs/meiduo_mall/lib/python3.5/site-packages/jinja2/loaders.py", line 125, in load
    code = environment.compile(source, name, filename)
  File "/home/python/.virtualenvs/meiduo_mall/lib/python3.5/site-packages/jinja2/environment.py", line 591, in compile
    self.handle_exception(exc_info, source_hint=source_hint)
  File "/home/python/.virtualenvs/meiduo_mall/lib/python3.5/site-packages/jinja2/environment.py", line 780, in handle_exception
    reraise(exc_type, exc_value, tb)
  File "/home/python/.virtualenvs/meiduo_mall/lib/python3.5/site-packages/jinja2/_compat.py", line 37, in reraise
    raise value.with_traceback(tb)
  File "/home/python/Desktop/meiduo_project/meiduo_mall/meiduo_mall/templates/register.html", line 28, in template
    {% csrf_token %}
  File "/home/python/.virtualenvs/meiduo_mall/lib/python3.5/site-packages/jinja2/environment.py", line 497, in _parse
    return Parser(self, source, name, encode_filename(filename)).parse()
  File "/home/python/.virtualenvs/meiduo_mall/lib/python3.5/site-packages/jinja2/parser.py", line 901, in parse
    result = nodes.Template(self.subparse(), lineno=1)
  File "/home/python/.virtualenvs/meiduo_mall/lib/python3.5/site-packages/jinja2/parser.py", line 883, in subparse
    rv = self.parse_statement()
  File "/home/python/.virtualenvs/meiduo_mall/lib/python3.5/site-packages/jinja2/parser.py", line 144, in parse_statement
    self.fail_unknown_tag(token.value, token.lineno)
  File "/home/python/.virtualenvs/meiduo_mall/lib/python3.5/site-packages/jinja2/parser.py", line 97, in fail_unknown_tag
    return self._fail_ut_eof(name, self._end_token_stack, lineno)
  File "/home/python/.virtualenvs/meiduo_mall/lib/python3.5/site-packages/jinja2/parser.py", line 90, in _fail_ut_eof
    self.fail(' '.join(message), lineno)
  File "/home/python/.virtualenvs/meiduo_mall/lib/python3.5/site-packages/jinja2/parser.py", line 59, in fail
    raise exc(msg, lineno, self.name, self.filename)
jinja2.exceptions.TemplateSyntaxError: Encountered unknown tag 'csrf_token'.

During handling of the above exception, another exception occurred:

Traceback (most recent call last):
  File "/home/python/.virtualenvs/meiduo_mall/lib/python3.5/site-packages/django/core/handlers/exception.py", line 41, in inner
    response = get_response(request)
  File "/home/python/.virtualenvs/meiduo_mall/lib/python3.5/site-packages/django/core/handlers/base.py", line 187, in _get_response
    response = self.process_exception_by_middleware(e, request)
  File "/home/python/.virtualenvs/meiduo_mall/lib/python3.5/site-packages/django/core/handlers/base.py", line 185, in _get_response
    response = wrapped_callback(request, *callback_args, **callback_kwargs)
  File "/home/python/.virtualenvs/meiduo_mall/lib/python3.5/site-packages/django/views/generic/base.py", line 68, in view
    return self.dispatch(request, *args, **kwargs)
  File "/home/python/.virtualenvs/meiduo_mall/lib/python3.5/site-packages/django/views/generic/base.py", line 88, in dispatch
    return handler(request, *args, **kwargs)
  File "/home/python/Desktop/meiduo_project/meiduo_mall/meiduo_mall/apps/users/views.py", line 23, in get
    return render(request, 'register.html')
  File "/home/python/.virtualenvs/meiduo_mall/lib/python3.5/site-packages/django/shortcuts.py", line 30, in render
    content = loader.render_to_string(template_name, context, request, using=using)
  File "/home/python/.virtualenvs/meiduo_mall/lib/python3.5/site-packages/django/template/loader.py", line 67, in render_to_string
    template = get_template(template_name, using=using)
  File "/home/python/.virtualenvs/meiduo_mall/lib/python3.5/site-packages/django/template/loader.py", line 21, in get_template
    return engine.get_template(template_name)
  File "/home/python/.virtualenvs/meiduo_mall/lib/python3.5/site-packages/django/template/backends/jinja2.py", line 55, in get_template
    six.reraise(TemplateSyntaxError, new, sys.exc_info()[2])
  File "/home/python/.virtualenvs/meiduo_mall/lib/python3.5/site-packages/django/utils/six.py", line 685, in reraise
    raise value.with_traceback(tb)
  File "/home/python/.virtualenvs/meiduo_mall/lib/python3.5/site-packages/django/template/backends/jinja2.py", line 45, in get_template
    return Template(self.env.get_template(template_name), self)
  File "/home/python/.virtualenvs/meiduo_mall/lib/python3.5/site-packages/jinja2/environment.py", line 830, in get_template
    return self._load_template(name, self.make_globals(globals))
  File "/home/python/.virtualenvs/meiduo_mall/lib/python3.5/site-packages/jinja2/environment.py", line 804, in _load_template
    template = self.loader.load(self, name, globals)
  File "/home/python/.virtualenvs/meiduo_mall/lib/python3.5/site-packages/jinja2/loaders.py", line 125, in load
    code = environment.compile(source, name, filename)
  File "/home/python/.virtualenvs/meiduo_mall/lib/python3.5/site-packages/jinja2/environment.py", line 591, in compile
    self.handle_exception(exc_info, source_hint=source_hint)
  File "/home/python/.virtualenvs/meiduo_mall/lib/python3.5/site-packages/jinja2/environment.py", line 780, in handle_exception
    reraise(exc_type, exc_value, tb)
  File "/home/python/.virtualenvs/meiduo_mall/lib/python3.5/site-packages/jinja2/_compat.py", line 37, in reraise
    raise value.with_traceback(tb)
  File "/home/python/Desktop/meiduo_project/meiduo_mall/meiduo_mall/templates/register.html", line 28, in template
    {% csrf_token %}
  File "/home/python/.virtualenvs/meiduo_mall/lib/python3.5/site-packages/jinja2/environment.py", line 497, in _parse
    return Parser(self, source, name, encode_filename(filename)).parse()
  File "/home/python/.virtualenvs/meiduo_mall/lib/python3.5/site-packages/jinja2/parser.py", line 901, in parse
    result = nodes.Template(self.subparse(), lineno=1)
  File "/home/python/.virtualenvs/meiduo_mall/lib/python3.5/site-packages/jinja2/parser.py", line 883, in subparse
    rv = self.parse_statement()
  File "/home/python/.virtualenvs/meiduo_mall/lib/python3.5/site-packages/jinja2/parser.py", line 144, in parse_statement
    self.fail_unknown_tag(token.value, token.lineno)
  File "/home/python/.virtualenvs/meiduo_mall/lib/python3.5/site-packages/jinja2/parser.py", line 97, in fail_unknown_tag
    return self._fail_ut_eof(name, self._end_token_stack, lineno)
  File "/home/python/.virtualenvs/meiduo_mall/lib/python3.5/site-packages/jinja2/parser.py", line 90, in _fail_ut_eof
    self.fail(' '.join(message), lineno)
  File "/home/python/.virtualenvs/meiduo_mall/lib/python3.5/site-packages/jinja2/parser.py", line 59, in fail
    raise exc(msg, lineno, self.name, self.filename)
django.template.exceptions.TemplateSyntaxError: ("Encountered unknown tag 'csrf_token'.",)
ERROR 2019-04-23 07:53:36,733 basehttp 124 "GET /register/ HTTP/1.1" 500 316552
INFO 2019-04-23 07:54:25,414 basehttp 124 "GET /register/ HTTP/1.1" 200 4526
WARNING 2019-04-23 07:54:45,171 basehttp 124 "POST /register/ HTTP/1.1" 403 12
INFO 2019-04-23 09:43:55,395 basehttp 124 "GET /register/ HTTP/1.1" 200 4526
INFO 2019-04-23 09:47:01,764 basehttp 124 "GET /register/ HTTP/1.1" 200 4526
WARNING 2019-04-23 09:52:42,385 basehttp 124 "POST /register/ HTTP/1.1" 403 12
WARNING 2019-04-23 09:54:05,575 basehttp 124 "POST /register/ HTTP/1.1" 403 12
INFO 2019-04-23 09:54:46,671 basehttp 124 "GET /register/ HTTP/1.1" 200 4526
WARNING 2019-04-23 09:55:06,897 basehttp 124 "POST /register/ HTTP/1.1" 403 12
INFO 2019-04-23 09:57:01,248 basehttp 124 "GET /register/ HTTP/1.1" 200 4526
WARNING 2019-04-23 09:57:22,960 basehttp 124 "POST /register/ HTTP/1.1" 403 12
WARNING 2019-04-23 09:58:14,102 basehttp 124 "POST /register/ HTTP/1.1" 403 12
INFO 2019-04-23 10:00:27,458 basehttp 124 "GET /register/ HTTP/1.1" 200 4526
WARNING 2019-04-23 10:00:43,067 basehttp 124 "POST /register/ HTTP/1.1" 403 12
INFO 2019-04-23 11:43:01,995 basehttp 124 "GET /register/ HTTP/1.1" 200 4526
INFO 2019-04-23 11:43:02,394 basehttp 124 "GET /static/css/reset.css HTTP/1.1" 304 0
INFO 2019-04-23 11:43:02,396 basehttp 124 "GET /static/css/main.css HTTP/1.1" 304 0
INFO 2019-04-23 11:43:02,397 basehttp 124 "GET /static/js/host.js HTTP/1.1" 200 120
INFO 2019-04-23 11:43:02,398 basehttp 124 "GET /static/js/vue-2.5.16.js HTTP/1.1" 304 0
INFO 2019-04-23 11:43:02,400 basehttp 124 "GET /static/js/axios-0.18.0.min.js HTTP/1.1" 304 0
INFO 2019-04-23 11:43:02,402 basehttp 124 "GET /static/images/logo.png HTTP/1.1" 304 0
INFO 2019-04-23 11:43:02,413 basehttp 124 "GET /static/js/register.js HTTP/1.1" 200 9786
ERROR 2019-04-23 11:43:02,725 exception 135 Internal Server Error: /image_codes/7c9d891b-bba0-435c-9cdc-e3a808bb598c/
Traceback (most recent call last):
  File "/home/python/.virtualenvs/meiduo_mall/lib/python3.5/site-packages/django/core/handlers/exception.py", line 41, in inner
    response = get_response(request)
  File "/home/python/.virtualenvs/meiduo_mall/lib/python3.5/site-packages/django/core/handlers/base.py", line 187, in _get_response
    response = self.process_exception_by_middleware(e, request)
  File "/home/python/.virtualenvs/meiduo_mall/lib/python3.5/site-packages/django/core/handlers/base.py", line 185, in _get_response
    response = wrapped_callback(request, *callback_args, **callback_kwargs)
  File "/home/python/.virtualenvs/meiduo_mall/lib/python3.5/site-packages/django/views/generic/base.py", line 68, in view
    return self.dispatch(request, *args, **kwargs)
  File "/home/python/.virtualenvs/meiduo_mall/lib/python3.5/site-packages/django/views/generic/base.py", line 88, in dispatch
    return handler(request, *args, **kwargs)
  File "/home/python/Desktop/meiduo_project/meiduo_mall/meiduo_mall/apps/verifications/views.py", line 22, in get
    text, code,image = captcha.generate_captcha()
AttributeError: module 'captcha' has no attribute 'generate_captcha'
ERROR 2019-04-23 11:43:03,023 basehttp 124 "GET /image_codes/7c9d891b-bba0-435c-9cdc-e3a808bb598c/ HTTP/1.1" 500 85249
WARNING 2019-04-23 11:43:11,804 base 152 Not Found: /usernames/guojia/count/
WARNING 2019-04-23 11:43:11,812 basehttp 124 "GET /usernames/guojia/count/ HTTP/1.1" 404 2855
WARNING 2019-04-23 11:43:23,882 base 152 Not Found: /mobiles/15763949168/count/
WARNING 2019-04-23 11:43:23,887 basehttp 124 "GET /mobiles/15763949168/count/ HTTP/1.1" 404 2864
WARNING 2019-04-23 11:43:29,361 base 152 Not Found: /usernames/guojia/count/
WARNING 2019-04-23 11:43:29,362 basehttp 124 "GET /usernames/guojia/count/ HTTP/1.1" 404 2855
WARNING 2019-04-23 11:43:29,414 base 152 Not Found: /mobiles/15763949168/count/
WARNING 2019-04-23 11:43:29,417 basehttp 124 "GET /mobiles/15763949168/count/ HTTP/1.1" 404 2864
WARNING 2019-04-23 11:43:29,436 basehttp 124 "POST /register/ HTTP/1.1" 403 12
INFO 2019-04-23 11:48:30,605 basehttp 124 "GET /register/ HTTP/1.1" 200 4526
ERROR 2019-04-23 11:48:31,027 exception 135 Internal Server Error: /image_codes/aedb1a33-03f2-4136-b68a-6a14db90221a/
Traceback (most recent call last):
  File "/home/python/.virtualenvs/meiduo_mall/lib/python3.5/site-packages/django/core/handlers/exception.py", line 41, in inner
    response = get_response(request)
  File "/home/python/.virtualenvs/meiduo_mall/lib/python3.5/site-packages/django/core/handlers/base.py", line 187, in _get_response
    response = self.process_exception_by_middleware(e, request)
  File "/home/python/.virtualenvs/meiduo_mall/lib/python3.5/site-packages/django/core/handlers/base.py", line 185, in _get_response
    response = wrapped_callback(request, *callback_args, **callback_kwargs)
  File "/home/python/.virtualenvs/meiduo_mall/lib/python3.5/site-packages/django/views/generic/base.py", line 68, in view
    return self.dispatch(request, *args, **kwargs)
  File "/home/python/.virtualenvs/meiduo_mall/lib/python3.5/site-packages/django/views/generic/base.py", line 88, in dispatch
    return handler(request, *args, **kwargs)
  File "/home/python/Desktop/meiduo_project/meiduo_mall/meiduo_mall/apps/verifications/views.py", line 22, in get
    text, code,image = captcha.generate_captcha()
AttributeError: module 'captcha' has no attribute 'generate_captcha'
ERROR 2019-04-23 11:48:31,213 basehttp 124 "GET /image_codes/aedb1a33-03f2-4136-b68a-6a14db90221a/ HTTP/1.1" 500 85249
WARNING 2019-04-23 11:48:35,596 base 152 Not Found: /usernames/python/count/
WARNING 2019-04-23 11:48:35,596 basehttp 124 "GET /usernames/python/count/ HTTP/1.1" 404 2855
WARNING 2019-04-23 11:48:44,328 base 152 Not Found: /mobiles/15763949168/count/
WARNING 2019-04-23 11:48:44,330 basehttp 124 "GET /mobiles/15763949168/count/ HTTP/1.1" 404 2864
WARNING 2019-04-23 11:48:48,042 base 152 Not Found: /usernames/python/count/
WARNING 2019-04-23 11:48:48,042 basehttp 124 "GET /usernames/python/count/ HTTP/1.1" 404 2855
WARNING 2019-04-23 11:48:48,278 base 152 Not Found: /mobiles/15763949168/count/
WARNING 2019-04-23 11:48:48,284 basehttp 124 "GET /mobiles/15763949168/count/ HTTP/1.1" 404 2864
ERROR 2019-04-23 11:48:48,310 exception 135 Internal Server Error: /register/
Traceback (most recent call last):
  File "/home/python/.virtualenvs/meiduo_mall/lib/python3.5/site-packages/django/core/handlers/exception.py", line 41, in inner
    response = get_response(request)
  File "/home/python/.virtualenvs/meiduo_mall/lib/python3.5/site-packages/django/core/handlers/base.py", line 187, in _get_response
    response = self.process_exception_by_middleware(e, request)
  File "/home/python/.virtualenvs/meiduo_mall/lib/python3.5/site-packages/django/core/handlers/base.py", line 185, in _get_response
    response = wrapped_callback(request, *callback_args, **callback_kwargs)
  File "/home/python/.virtualenvs/meiduo_mall/lib/python3.5/site-packages/django/views/generic/base.py", line 68, in view
    return self.dispatch(request, *args, **kwargs)
  File "/home/python/.virtualenvs/meiduo_mall/lib/python3.5/site-packages/django/views/generic/base.py", line 88, in dispatch
    return handler(request, *args, **kwargs)
  File "/home/python/Desktop/meiduo_project/meiduo_mall/meiduo_mall/apps/users/views.py", line 49, in post
    if User.objects.filter(mobile = mobile).count() > 0:
  File "/home/python/.virtualenvs/meiduo_mall/lib/python3.5/site-packages/django/db/models/manager.py", line 198, in __get__
    cls._meta.swapped,
AttributeError: Manager isn't available; 'auth.User' has been swapped for 'users.User'
ERROR 2019-04-23 11:48:48,589 basehttp 124 "POST /register/ HTTP/1.1" 500 90662
INFO 2019-04-23 11:57:38,377 basehttp 124 "GET /register/ HTTP/1.1" 200 4526
INFO 2019-04-23 11:57:38,602 basehttp 124 "GET /static/js/host.js HTTP/1.1" 304 0
INFO 2019-04-23 11:57:38,603 basehttp 124 "GET /static/js/register.js HTTP/1.1" 304 0
ERROR 2019-04-23 11:57:38,878 exception 135 Internal Server Error: /image_codes/6bf5ad46-db7f-444d-91b8-14f908b34091/
Traceback (most recent call last):
  File "/home/python/.virtualenvs/meiduo_mall/lib/python3.5/site-packages/django/core/handlers/exception.py", line 41, in inner
    response = get_response(request)
  File "/home/python/.virtualenvs/meiduo_mall/lib/python3.5/site-packages/django/core/handlers/base.py", line 187, in _get_response
    response = self.process_exception_by_middleware(e, request)
  File "/home/python/.virtualenvs/meiduo_mall/lib/python3.5/site-packages/django/core/handlers/base.py", line 185, in _get_response
    response = wrapped_callback(request, *callback_args, **callback_kwargs)
  File "/home/python/.virtualenvs/meiduo_mall/lib/python3.5/site-packages/django/views/generic/base.py", line 68, in view
    return self.dispatch(request, *args, **kwargs)
  File "/home/python/.virtualenvs/meiduo_mall/lib/python3.5/site-packages/django/views/generic/base.py", line 88, in dispatch
    return handler(request, *args, **kwargs)
  File "/home/python/Desktop/meiduo_project/meiduo_mall/meiduo_mall/apps/verifications/views.py", line 22, in get
    text, code,image = captcha.generate_captcha()
AttributeError: module 'captcha' has no attribute 'generate_captcha'
ERROR 2019-04-23 11:57:39,033 basehttp 124 "GET /image_codes/6bf5ad46-db7f-444d-91b8-14f908b34091/ HTTP/1.1" 500 85249
WARNING 2019-04-23 12:00:49,582 base 152 Not Found: /usernames/guojia/count/
WARNING 2019-04-23 12:00:49,584 basehttp 124 "GET /usernames/guojia/count/ HTTP/1.1" 404 2855
WARNING 2019-04-23 12:01:01,728 base 152 Not Found: /mobiles/15763949168/count/
WARNING 2019-04-23 12:01:01,738 basehttp 124 "GET /mobiles/15763949168/count/ HTTP/1.1" 404 2864
WARNING 2019-04-23 12:01:06,282 base 152 Not Found: /usernames/guojia/count/
WARNING 2019-04-23 12:01:06,282 basehttp 124 "GET /usernames/guojia/count/ HTTP/1.1" 404 2855
WARNING 2019-04-23 12:01:06,288 base 152 Not Found: /mobiles/15763949168/count/
WARNING 2019-04-23 12:01:06,292 basehttp 124 "GET /mobiles/15763949168/count/ HTTP/1.1" 404 2864
ERROR 2019-04-23 12:01:07,408 exception 135 Internal Server Error: /register/
Traceback (most recent call last):
  File "/home/python/.virtualenvs/meiduo_mall/lib/python3.5/site-packages/django_redis/cache.py", line 32, in _decorator
    return method(self, *args, **kwargs)
  File "/home/python/.virtualenvs/meiduo_mall/lib/python3.5/site-packages/django_redis/cache.py", line 124, in has_key
    return self.client.has_key(*args, **kwargs)
  File "/home/python/.virtualenvs/meiduo_mall/lib/python3.5/site-packages/django_redis/client/default.py", line 478, in has_key
    raise ConnectionInterrupted(connection=client, parent=e)
django_redis.exceptions.ConnectionInterrupted: Redis ConnectionError: Error 111 connecting to 127.0.0.1:6379. Connection refused.

During handling of the above exception, another exception occurred:

Traceback (most recent call last):
  File "/home/python/.virtualenvs/meiduo_mall/lib/python3.5/site-packages/django/core/handlers/exception.py", line 41, in inner
    response = get_response(request)
  File "/home/python/.virtualenvs/meiduo_mall/lib/python3.5/site-packages/django/core/handlers/base.py", line 187, in _get_response
    response = self.process_exception_by_middleware(e, request)
  File "/home/python/.virtualenvs/meiduo_mall/lib/python3.5/site-packages/django/core/handlers/base.py", line 185, in _get_response
    response = wrapped_callback(request, *callback_args, **callback_kwargs)
  File "/home/python/.virtualenvs/meiduo_mall/lib/python3.5/site-packages/django/views/generic/base.py", line 68, in view
    return self.dispatch(request, *args, **kwargs)
  File "/home/python/.virtualenvs/meiduo_mall/lib/python3.5/site-packages/django/views/generic/base.py", line 88, in dispatch
    return handler(request, *args, **kwargs)
  File "/home/python/Desktop/meiduo_project/meiduo_mall/meiduo_mall/apps/users/views.py", line 67, in post
    login(request, user)
  File "/home/python/.virtualenvs/meiduo_mall/lib/python3.5/site-packages/django/contrib/auth/__init__.py", line 140, in login
    request.session.cycle_key()
  File "/home/python/.virtualenvs/meiduo_mall/lib/python3.5/site-packages/django/contrib/sessions/backends/base.py", line 311, in cycle_key
    self.create()
  File "/home/python/.virtualenvs/meiduo_mall/lib/python3.5/site-packages/django/contrib/sessions/backends/cache.py", line 44, in create
    self._session_key = self._get_new_session_key()
  File "/home/python/.virtualenvs/meiduo_mall/lib/python3.5/site-packages/django/contrib/sessions/backends/base.py", line 164, in _get_new_session_key
    if not self.exists(session_key):
  File "/home/python/.virtualenvs/meiduo_mall/lib/python3.5/site-packages/django/contrib/sessions/backends/cache.py", line 71, in exists
    return session_key and (self.cache_key_prefix + session_key) in self._cache
  File "/home/python/.virtualenvs/meiduo_mall/lib/python3.5/site-packages/django/core/cache/backends/base.py", line 203, in __contains__
    return self.has_key(key)
  File "/home/python/.virtualenvs/meiduo_mall/lib/python3.5/site-packages/django_redis/cache.py", line 39, in _decorator
    raise e.parent
  File "/home/python/.virtualenvs/meiduo_mall/lib/python3.5/site-packages/django_redis/client/default.py", line 476, in has_key
    return client.exists(key) == 1
  File "/home/python/.virtualenvs/meiduo_mall/lib/python3.5/site-packages/redis/client.py", line 1239, in exists
    return self.execute_command('EXISTS', *names)
  File "/home/python/.virtualenvs/meiduo_mall/lib/python3.5/site-packages/redis/client.py", line 772, in execute_command
    connection = pool.get_connection(command_name, **options)
  File "/home/python/.virtualenvs/meiduo_mall/lib/python3.5/site-packages/redis/connection.py", line 994, in get_connection
    connection.connect()
  File "/home/python/.virtualenvs/meiduo_mall/lib/python3.5/site-packages/redis/connection.py", line 497, in connect
    raise ConnectionError(self._error_message(e))
redis.exceptions.ConnectionError: Error 111 connecting to 127.0.0.1:6379. Connection refused.
ERROR 2019-04-23 12:01:07,746 basehttp 124 "POST /register/ HTTP/1.1" 500 149957
INFO 2019-04-23 12:02:50,094 basehttp 124 "GET /register/ HTTP/1.1" 200 4526
ERROR 2019-04-23 12:02:50,688 exception 135 Internal Server Error: /image_codes/dbea2255-fa34-4e58-9775-2cd9d919ad1d/
Traceback (most recent call last):
  File "/home/python/.virtualenvs/meiduo_mall/lib/python3.5/site-packages/django/core/handlers/exception.py", line 41, in inner
    response = get_response(request)
  File "/home/python/.virtualenvs/meiduo_mall/lib/python3.5/site-packages/django/core/handlers/base.py", line 187, in _get_response
    response = self.process_exception_by_middleware(e, request)
  File "/home/python/.virtualenvs/meiduo_mall/lib/python3.5/site-packages/django/core/handlers/base.py", line 185, in _get_response
    response = wrapped_callback(request, *callback_args, **callback_kwargs)
  File "/home/python/.virtualenvs/meiduo_mall/lib/python3.5/site-packages/django/views/generic/base.py", line 68, in view
    return self.dispatch(request, *args, **kwargs)
  File "/home/python/.virtualenvs/meiduo_mall/lib/python3.5/site-packages/django/views/generic/base.py", line 88, in dispatch
    return handler(request, *args, **kwargs)
  File "/home/python/Desktop/meiduo_project/meiduo_mall/meiduo_mall/apps/verifications/views.py", line 22, in get
    text, code,image = captcha.generate_captcha()
AttributeError: module 'captcha' has no attribute 'generate_captcha'
ERROR 2019-04-23 12:02:50,843 basehttp 124 "GET /image_codes/dbea2255-fa34-4e58-9775-2cd9d919ad1d/ HTTP/1.1" 500 85351
WARNING 2019-04-23 12:02:54,345 base 152 Not Found: /usernames/guojia/count/
WARNING 2019-04-23 12:02:54,350 basehttp 124 "GET /usernames/guojia/count/ HTTP/1.1" 404 2855
WARNING 2019-04-23 12:03:06,032 base 152 Not Found: /mobiles/15763949168/count/
WARNING 2019-04-23 12:03:06,043 basehttp 124 "GET /mobiles/15763949168/count/ HTTP/1.1" 404 2864
WARNING 2019-04-23 12:03:09,832 base 152 Not Found: /usernames/guojia/count/
WARNING 2019-04-23 12:03:09,836 basehttp 124 "GET /usernames/guojia/count/ HTTP/1.1" 404 2855
WARNING 2019-04-23 12:03:09,852 base 152 Not Found: /mobiles/15763949168/count/
WARNING 2019-04-23 12:03:09,859 basehttp 124 "GET /mobiles/15763949168/count/ HTTP/1.1" 404 2864
WARNING 2019-04-23 12:03:10,069 basehttp 124 "POST /register/ HTTP/1.1" 400 18
ERROR 2019-04-23 12:03:16,696 exception 135 Internal Server Error: /image_codes/a1555910-d40f-4f63-94df-3a82e4e10440/
Traceback (most recent call last):
  File "/home/python/.virtualenvs/meiduo_mall/lib/python3.5/site-packages/django/core/handlers/exception.py", line 41, in inner
    response = get_response(request)
  File "/home/python/.virtualenvs/meiduo_mall/lib/python3.5/site-packages/django/core/handlers/base.py", line 187, in _get_response
    response = self.process_exception_by_middleware(e, request)
  File "/home/python/.virtualenvs/meiduo_mall/lib/python3.5/site-packages/django/core/handlers/base.py", line 185, in _get_response
    response = wrapped_callback(request, *callback_args, **callback_kwargs)
  File "/home/python/.virtualenvs/meiduo_mall/lib/python3.5/site-packages/django/views/generic/base.py", line 68, in view
    return self.dispatch(request, *args, **kwargs)
  File "/home/python/.virtualenvs/meiduo_mall/lib/python3.5/site-packages/django/views/generic/base.py", line 88, in dispatch
    return handler(request, *args, **kwargs)
  File "/home/python/Desktop/meiduo_project/meiduo_mall/meiduo_mall/apps/verifications/views.py", line 22, in get
    text, code,image = captcha.generate_captcha()
AttributeError: module 'captcha' has no attribute 'generate_captcha'
ERROR 2019-04-23 12:03:16,807 basehttp 124 "GET /image_codes/a1555910-d40f-4f63-94df-3a82e4e10440/ HTTP/1.1" 500 85351
WARNING 2019-04-23 12:03:20,001 base 152 Not Found: /usernames/guohongyan/count/
WARNING 2019-04-23 12:03:20,013 basehttp 124 "GET /usernames/guohongyan/count/ HTTP/1.1" 404 2867
WARNING 2019-04-23 12:03:31,246 base 152 Not Found: /mobiles/13904451155/count/
WARNING 2019-04-23 12:03:31,258 basehttp 124 "GET /mobiles/13904451155/count/ HTTP/1.1" 404 2864
WARNING 2019-04-23 12:03:35,879 base 152 Not Found: /usernames/guohongyan/count/
WARNING 2019-04-23 12:03:35,883 basehttp 124 "GET /usernames/guohongyan/count/ HTTP/1.1" 404 2867
WARNING 2019-04-23 12:03:35,888 base 152 Not Found: /mobiles/13904451155/count/
WARNING 2019-04-23 12:03:35,892 basehttp 124 "GET /mobiles/13904451155/count/ HTTP/1.1" 404 2864
ERROR 2019-04-23 12:03:36,080 exception 135 Internal Server Error: /register/
Traceback (most recent call last):
  File "/home/python/.virtualenvs/meiduo_mall/lib/python3.5/site-packages/django_redis/cache.py", line 32, in _decorator
    return method(self, *args, **kwargs)
  File "/home/python/.virtualenvs/meiduo_mall/lib/python3.5/site-packages/django_redis/cache.py", line 124, in has_key
    return self.client.has_key(*args, **kwargs)
  File "/home/python/.virtualenvs/meiduo_mall/lib/python3.5/site-packages/django_redis/client/default.py", line 478, in has_key
    raise ConnectionInterrupted(connection=client, parent=e)
django_redis.exceptions.ConnectionInterrupted: Redis ConnectionError: Error 111 connecting to 127.0.0.1:6379. Connection refused.

During handling of the above exception, another exception occurred:

Traceback (most recent call last):
  File "/home/python/.virtualenvs/meiduo_mall/lib/python3.5/site-packages/django/core/handlers/exception.py", line 41, in inner
    response = get_response(request)
  File "/home/python/.virtualenvs/meiduo_mall/lib/python3.5/site-packages/django/core/handlers/base.py", line 187, in _get_response
    response = self.process_exception_by_middleware(e, request)
  File "/home/python/.virtualenvs/meiduo_mall/lib/python3.5/site-packages/django/core/handlers/base.py", line 185, in _get_response
    response = wrapped_callback(request, *callback_args, **callback_kwargs)
  File "/home/python/.virtualenvs/meiduo_mall/lib/python3.5/site-packages/django/views/generic/base.py", line 68, in view
    return self.dispatch(request, *args, **kwargs)
  File "/home/python/.virtualenvs/meiduo_mall/lib/python3.5/site-packages/django/views/generic/base.py", line 88, in dispatch
    return handler(request, *args, **kwargs)
  File "/home/python/Desktop/meiduo_project/meiduo_mall/meiduo_mall/apps/users/views.py", line 67, in post
    login(request, user)
  File "/home/python/.virtualenvs/meiduo_mall/lib/python3.5/site-packages/django/contrib/auth/__init__.py", line 140, in login
    request.session.cycle_key()
  File "/home/python/.virtualenvs/meiduo_mall/lib/python3.5/site-packages/django/contrib/sessions/backends/base.py", line 311, in cycle_key
    self.create()
  File "/home/python/.virtualenvs/meiduo_mall/lib/python3.5/site-packages/django/contrib/sessions/backends/cache.py", line 44, in create
    self._session_key = self._get_new_session_key()
  File "/home/python/.virtualenvs/meiduo_mall/lib/python3.5/site-packages/django/contrib/sessions/backends/base.py", line 164, in _get_new_session_key
    if not self.exists(session_key):
  File "/home/python/.virtualenvs/meiduo_mall/lib/python3.5/site-packages/django/contrib/sessions/backends/cache.py", line 71, in exists
    return session_key and (self.cache_key_prefix + session_key) in self._cache
  File "/home/python/.virtualenvs/meiduo_mall/lib/python3.5/site-packages/django/core/cache/backends/base.py", line 203, in __contains__
    return self.has_key(key)
  File "/home/python/.virtualenvs/meiduo_mall/lib/python3.5/site-packages/django_redis/cache.py", line 39, in _decorator
    raise e.parent
  File "/home/python/.virtualenvs/meiduo_mall/lib/python3.5/site-packages/django_redis/client/default.py", line 476, in has_key
    return client.exists(key) == 1
  File "/home/python/.virtualenvs/meiduo_mall/lib/python3.5/site-packages/redis/client.py", line 1239, in exists
    return self.execute_command('EXISTS', *names)
  File "/home/python/.virtualenvs/meiduo_mall/lib/python3.5/site-packages/redis/client.py", line 772, in execute_command
    connection = pool.get_connection(command_name, **options)
  File "/home/python/.virtualenvs/meiduo_mall/lib/python3.5/site-packages/redis/connection.py", line 994, in get_connection
    connection.connect()
  File "/home/python/.virtualenvs/meiduo_mall/lib/python3.5/site-packages/redis/connection.py", line 497, in connect
    raise ConnectionError(self._error_message(e))
redis.exceptions.ConnectionError: Error 111 connecting to 127.0.0.1:6379. Connection refused.
ERROR 2019-04-23 12:03:36,368 basehttp 124 "POST /register/ HTTP/1.1" 500 150075
ERROR 2019-04-23 12:09:12,257 exception 135 Internal Server Error: /image_codes/6fff9100-812d-48de-bcab-fae59b71d60e/
Traceback (most recent call last):
  File "/home/python/.virtualenvs/meiduo_mall/lib/python3.5/site-packages/django/core/handlers/exception.py", line 41, in inner
    response = get_response(request)
  File "/home/python/.virtualenvs/meiduo_mall/lib/python3.5/site-packages/django/core/handlers/base.py", line 187, in _get_response
    response = self.process_exception_by_middleware(e, request)
  File "/home/python/.virtualenvs/meiduo_mall/lib/python3.5/site-packages/django/core/handlers/base.py", line 185, in _get_response
    response = wrapped_callback(request, *callback_args, **callback_kwargs)
  File "/home/python/.virtualenvs/meiduo_mall/lib/python3.5/site-packages/django/views/generic/base.py", line 68, in view
    return self.dispatch(request, *args, **kwargs)
  File "/home/python/.virtualenvs/meiduo_mall/lib/python3.5/site-packages/django/views/generic/base.py", line 88, in dispatch
    return handler(request, *args, **kwargs)
  File "/home/python/Desktop/meiduo_project/meiduo_mall/meiduo_mall/apps/verifications/views.py", line 22, in get
    text, code,image = captcha.generate_captcha()
AttributeError: module 'captcha' has no attribute 'generate_captcha'
ERROR 2019-04-23 12:09:12,544 basehttp 124 "GET /image_codes/6fff9100-812d-48de-bcab-fae59b71d60e/ HTTP/1.1" 500 85351
INFO 2019-04-23 12:13:25,182 basehttp 124 "GET /register/ HTTP/1.1" 200 4526
INFO 2019-04-23 12:13:25,240 basehttp 124 "GET /static/js/host.js HTTP/1.1" 304 0
INFO 2019-04-23 12:13:25,243 basehttp 124 "GET /static/js/register.js HTTP/1.1" 304 0
ERROR 2019-04-23 12:13:25,484 exception 135 Internal Server Error: /image_codes/f7ea5d78-d23e-4cff-a952-1320142c2558/
Traceback (most recent call last):
  File "/home/python/.virtualenvs/meiduo_mall/lib/python3.5/site-packages/django/core/handlers/exception.py", line 41, in inner
    response = get_response(request)
  File "/home/python/.virtualenvs/meiduo_mall/lib/python3.5/site-packages/django/core/handlers/base.py", line 187, in _get_response
    response = self.process_exception_by_middleware(e, request)
  File "/home/python/.virtualenvs/meiduo_mall/lib/python3.5/site-packages/django/core/handlers/base.py", line 185, in _get_response
    response = wrapped_callback(request, *callback_args, **callback_kwargs)
  File "/home/python/.virtualenvs/meiduo_mall/lib/python3.5/site-packages/django/views/generic/base.py", line 68, in view
    return self.dispatch(request, *args, **kwargs)
  File "/home/python/.virtualenvs/meiduo_mall/lib/python3.5/site-packages/django/views/generic/base.py", line 88, in dispatch
    return handler(request, *args, **kwargs)
  File "/home/python/Desktop/meiduo_project/meiduo_mall/meiduo_mall/apps/verifications/views.py", line 22, in get
    text, code,image = captcha.generate_captcha()
AttributeError: module 'captcha' has no attribute 'generate_captcha'
ERROR 2019-04-23 12:13:25,650 basehttp 124 "GET /image_codes/f7ea5d78-d23e-4cff-a952-1320142c2558/ HTTP/1.1" 500 85351
WARNING 2019-04-23 12:13:28,686 base 152 Not Found: /usernames/guojia/count/
WARNING 2019-04-23 12:13:28,689 basehttp 124 "GET /usernames/guojia/count/ HTTP/1.1" 404 2855
WARNING 2019-04-23 12:13:40,108 base 152 Not Found: /mobiles/15763949168/count/
WARNING 2019-04-23 12:13:40,109 basehttp 124 "GET /mobiles/15763949168/count/ HTTP/1.1" 404 2864
WARNING 2019-04-23 12:13:43,768 base 152 Not Found: /usernames/guojia/count/
WARNING 2019-04-23 12:13:43,773 basehttp 124 "GET /usernames/guojia/count/ HTTP/1.1" 404 2855
WARNING 2019-04-23 12:13:43,789 base 152 Not Found: /mobiles/15763949168/count/
WARNING 2019-04-23 12:13:43,789 basehttp 124 "GET /mobiles/15763949168/count/ HTTP/1.1" 404 2864
INFO 2019-04-23 12:13:44,339 basehttp 124 "POST /register/ HTTP/1.1" 302 0
INFO 2019-04-23 12:13:44,406 basehttp 124 "GET / HTTP/1.1" 200 25127
INFO 2019-04-23 12:13:44,467 basehttp 124 "GET /static/js/jquery-1.12.4.min.js HTTP/1.1" 304 0
INFO 2019-04-23 12:13:44,476 basehttp 124 "GET /static/images/goods/goods001.jpg HTTP/1.1" 304 0
INFO 2019-04-23 12:13:44,529 basehttp 124 "GET /static/images/goods/goods002.jpg HTTP/1.1" 304 0
INFO 2019-04-23 12:13:44,533 basehttp 124 "GET /static/images/slide01.jpg HTTP/1.1" 304 0
INFO 2019-04-23 12:13:44,536 basehttp 124 "GET /static/images/slide02.jpg HTTP/1.1" 304 0
INFO 2019-04-23 12:13:44,538 basehttp 124 "GET /static/images/slide03.jpg HTTP/1.1" 304 0
INFO 2019-04-23 12:13:44,539 basehttp 124 "GET /static/images/slide04.jpg HTTP/1.1" 304 0
INFO 2019-04-23 12:13:44,540 basehttp 124 "GET /static/images/adv01.jpg HTTP/1.1" 304 0
INFO 2019-04-23 12:13:44,587 basehttp 124 "GET /static/js/slide.js HTTP/1.1" 304 0
INFO 2019-04-23 12:13:44,588 basehttp 124 "GET /static/js/common.js HTTP/1.1" 304 0
INFO 2019-04-23 12:13:44,589 basehttp 124 "GET /static/js/index.js HTTP/1.1" 304 0
INFO 2019-04-23 12:13:44,594 basehttp 124 "GET /static/images/banner01.jpg HTTP/1.1" 304 0
INFO 2019-04-23 12:13:44,624 basehttp 124 "GET /static/images/goods/goods003.jpg HTTP/1.1" 304 0
INFO 2019-04-23 12:13:44,627 basehttp 124 "GET /static/images/goods/goods004.jpg HTTP/1.1" 304 0
INFO 2019-04-23 12:13:44,628 basehttp 124 "GET /static/images/goods/goods005.jpg HTTP/1.1" 304 0
INFO 2019-04-23 12:13:44,631 basehttp 124 "GET /static/images/banner02.jpg HTTP/1.1" 304 0
INFO 2019-04-23 12:13:44,635 basehttp 124 "GET /static/images/goods/goods008.jpg HTTP/1.1" 304 0
INFO 2019-04-23 12:13:44,642 basehttp 124 "GET /static/images/banner03.jpg HTTP/1.1" 304 0
INFO 2019-04-23 12:13:44,646 basehttp 124 "GET /static/images/goods/goods009.jpg HTTP/1.1" 304 0
WARNING 2019-04-23 12:13:45,851 base 152 Not Found: /carts/simple/
WARNING 2019-04-23 12:13:45,857 basehttp 124 "GET /carts/simple/ HTTP/1.1" 404 2825
